Workbook

Sheet Instructions
A1: Don't edit column L
A3: If the row is blank then leave if blank it is likely missing
A4: If there is an NA please put it there (as it indicates its dead)
A7: Oak Type
A8: NR = Natural Recruit | C8: Oak Type refers to how it was planted if at all.
A9: S = Seedling
A10: A = Acorn
A12: Treatment
A13: OA = Open Area | C13: Treatment refers to microclimate treatment (where it was planted).
A14: SA = Salvia apiana
A15: DT = Downed Tree
A16: AC = Adult Canopy
A17: NP = Nurse Plant
A18: DL = Dripline
A20: OA Microclimate
A21: CN = Control | C21: OA Microclimate refers to the treatment conducted on open area plots
A22: TH = Thatch removed
A23: TI = Thatch + Invasive Species Removed

Sheet Input1
A1: Page Number | B1: Date Collected | C1: Recorder | D1: Block | E1: Tag # | F1: Oak Type | G1: Treatment | H1: OA Microclimate | I1: Seedling Height | J1: # of Leaves | K1: # of dead leaves | L1: % Leaf Greeness | M1: # that germinated | N1: RCD | O1: Notes
A2: 2 | B2: 46133 | C2: Steven | D2: 7 | E2: 152 | F2: A | G2: OA | H2: NA | I2: 14 | J2: 14 | K2: 0 | L2: =IF(K2=0, 100, 100-(K2/J2)*100) -> 100 | M2: 1 | N2: 0.8
A3: 1 | B3: 46133 | C3: JA/SM | D3: 7 | E3: 204 | F3: NR | G3: AC | H3: NA | I3: 60 | J3: 90 | K3: 5 | L3: =IF(K3=0, 100, 100-(K3/J3)*100) -> 94.444444 | M3: NA | N3: 9
A4: 1 | B4: 46133 | C4: JA/SM | D4: 7 | E4: 218 | F4: NR | G4: DT | H4: NA | I4: 19 | J4: 15 | K4: 0 | L4: =IF(K4=0, 100, 100-(K4/J4)*100) -> 100 | M4: NA | N4: 4.1 | O4: Gopher
A5: 1 | B5: 46133 | C5: JA/SM | D5: 7 | E5: 219 | F5: NR | G5: DT | H5: NA | I5: 10 | J5: 12 | K5: 0 | L5: =IF(K5=0, 100, 100-(K5/J5)*100) -> 100 | M5: NA | N5: 2.7
A6: 1 | B6: 46133 | C6: JA/SM | D6: 7 | E6: 222 | F6: NR | G6: AC | H6: NA | I6: 20 | J6: 3 | K6: 0 | L6: =IF(K6=0, 100, 100-(K6/J6)*100) -> 100 | M6: NA | N6: 3
A7: 1 | B7: 46133 | C7: JA/SM | D7: 7 | E7: 224 | F7: NR | G7: DL | H7: NA | I7: 21 | J7: 9 | K7: 0 | L7: =IF(K7=0, 100, 100-(K7/J7)*100) -> 100 | M7: NA | N7: 2.9
A8: 2 | B8: 46133 | C8: Steven | D8: 6 | E8: 225 | F8: NR | G8: DT | H8: NA | I8: 30 | J8: 30 | K8: 0 | L8: =IF(K8=0, 100, 100-(K8/J8)*100) -> 100 | M8: NA | N8: 7.4
A9: 1 | B9: 46133 | C9: JA/SM | D9: 7 | E9: 236 | F9: A | G9: OA | H9: TH | I9: NA | J9: NA | K9: NA | L9: =IF(K9=0, 100, 100-(K9/J9)*100) -> #VALUE! | M9: NA | N9: NA
A10: 1 | B10: 46133 | C10: JA/SM | D10: 7 | E10: 237 | F10: A | G10: OA | H10: CN | I10: NA | J10: NA | K10: NA | L10: =IF(K10=0, 100, 100-(K10/J10)*100) -> #VALUE! | M10: NA | N10: NA
A11: 1 | B11: 46133 | C11: JA/SM | D11: 7 | E11: 238 | F11: A | G11: OA | H11: TI | I11: 8 | J11: 8 | K11: 0 | L11: =IF(K11=0, 100, 100-(K11/J11)*100) -> 100 | M11: 1 | N11: 2
A12: 1 | B12: 46133 | C12: JA/SM | D12: 7 | E12: 240 | F12: A | G12: DT | H12: NA | I12: NA | J12: NA | K12: NA | L12: =IF(K12=0, 100, 100-(K12/J12)*100) -> #VALUE! | M12: NA | N12: NA
A13: 1 | B13: 46133 | C13: JA/SM | D13: 7 | E13: 244 | F13: A | G13: AC | H13: NA | I13: NA | J13: NA | K13: NA | L13: =IF(K13=0, 100, 100-(K13/J13)*100) -> #VALUE! | M13: 0 | N13: NA | O13: No acorns germinated
A14: 2 | B14: 46133 | C14: Steven | D14: 6 | E14: 245 | F14: A | G14: OA | H14: TI | I14: NA | J14: NA | K14: NA | L14: =IF(K14=0, 100, 100-(K14/J14)*100) -> #VALUE! | M14: 0 | N14: NA
A15: 2 | B15: 46133 | C15: Steven | D15: 6 | E15: 246 | F15: A | G15: OA | H15: TH | I15: NA | J15: NA | K15: NA | L15: =IF(K15=0, 100, 100-(K15/J15)*100) -> #VALUE! | M15: 0 | N15: NA
A16: 2 | B16: 46133 | C16: Steven | D16: 6 | E16: 249 | F16: A | G16: DT | H16: NA | I16: NA | J16: NA | K16: NA | L16: =IF(K16=0, 100, 100-(K16/J16)*100) -> #VALUE! | M16: 0 | N16: NA
A17: 2 | B17: 46133 | C17: Steven | D17: 6 | E17: 251 | F17: A | G17: AC | H17: NA | I17: 11 | J17: 4 | K17: 0 | L17: =IF(K17=0, 100, 100-(K17/J17)*100) -> 100 | M17: 1 | N17: 1.2
A18: Page # | B18: MM/DD/YYYY | C18: Name | D18: # | E18: # | F18: NR, S, or A | G18: AC, OA, NP, DT, or DL | H18: TH, TI, CN | I18: (cm) | J18: # | K18: # | L18: % | M18: # | N18: (mm) | O18: as written on data sheet
A19: 2 | B19: 46133 | C19: Steven | D19: 6 | E19: 127A1 | F19: A | G19: OA | H19: NA | I19: 36 | J19: 50 | K19: 0 | L19: =IF(K19=0, 100, 100-(K19/J19)*100) -> 100 | M19: 2 | N19: 7.9
A20: 2 | B20: 46133 | C20: Steven | D20: 6 | E20: 127A2 | F20: A | G20: OA | H20: NA | I20: 43 | J20: 90 | K20: 1 | L20: =IF(K20=0, 100, 100-(K20/J20)*100) -> 98.888889 | M20: 2 | N20: 6.6
A21: 2 | B21: 46133 | C21: Steven | D21: 6 | E21: 129A1 | F21: A | G21: OA | H21: NA | I21: NA | J21: NA | K21: NA | L21: =IF(K21=0, 100, 100-(K21/J21)*100) -> #VALUE! | M21: NA | N21: NA
A22: 2 | B22: 46133 | C22: Steven | D22: 6 | E22: 129A2 | F22: A | G22: OA | H22: NA | I22: 18 | J22: 25 | K22: 8 | L22: =IF(K22=0, 100, 100-(K22/J22)*100) -> 68 | M22: 2 | N22: 2.3
A23: 1 | B23: 46133 | C23: JA/SM | D23: 7 | E23: 159A1 | F23: A | G23: AC | H23: NA | I23: 23 | J23: 14 | K23: 0 | L23: =IF(K23=0, 100, 100-(K23/J23)*100) -> 100 | M23: 3 | N23: 1.9
A24: 1 | B24: 46133 | C24: JA/SM | D24: 7 | E24: 159A2 | F24: A | G24: AC | H24: NA | I24: 15 | J24: 9 | K24: 0 | L24: =IF(K24=0, 100, 100-(K24/J24)*100) -> 100 | M24: 3 | N24: 1
A25: 1 | B25: 46133 | C25: JA/SM | D25: 7 | E25: 159A3 | F25: A | G25: AC | H25: NA | I25: 13 | J25: 6 | K25: 0 | L25: =IF(K25=0, 100, 100-(K25/J25)*100) -> 100 | M25: 3 | N25: 1.4
A26: 1 | B26: 46133 | C26: JA/SM | D26: 7 | E26: 239A1 | F26: A | G26: DT | H26: NA | I26: 21 | J26: 5 | K26: 0 | L26: =IF(K26=0, 100, 100-(K26/J26)*100) -> 100 | M26: 1 | N26: 2.1
A27: 1 | B27: 46133 | C27: JA/SM | D27: 7 | E27: 242A1 | F27: A | G27: AC | H27: NA | I27: 15 | J27: 4 | K27: 0 | L27: =IF(K27=0, 100, 100-(K27/J27)*100) -> 100 | M27: 3 | N27: 2.5
A28: 1 | B28: 46133 | C28: JA/SM | D28: 7 | E28: 242A2 | F28: A | G28: AC | H28: NA | I28: 20 | J28: 4 | K28: 0 | L28: =IF(K28=0, 100, 100-(K28/J28)*100) -> 100 | M28: 3 | N28: 2.9
A29: 1 | B29: 46133 | C29: JA/SM | D29: 7 | E29: 242A3 | F29: A | G29: AC | H29: NA | I29: 13 | J29: 5 | K29: 0 | L29: =IF(K29=0, 100, 100-(K29/J29)*100) -> 100 | M29: 3 | N29: 1.9 | O29: Herbivory on 1 leaf
A30: 1 | B30: 46133 | C30: JA/SM | D30: 7 | E30: 243A1 | F30: A | G30: AC | H30: NA | I30: 18 | J30: 2 | K30: 0 | L30: =IF(K30=0, 100, 100-(K30/J30)*100) -> 100 | M30: 2 | N30: 2.8
A31: 1 | B31: 46133 | C31: JA/SM | D31: 7 | E31: 243A2 | F31: A | G31: AC | H31: NA | I31: 12 | J31: 4 | K31: 0 | L31: =IF(K31=0, 100, 100-(K31/J31)*100) -> 100 | M31: 2 | N31: 1.5
A32: 2 | B32: 46133 | C32: Steven | D32: 6 | E32: 247A1 | F32: A | G32: OA | H32: CN | I32: 13 | J32: 5 | K32: 0 | L32: =IF(K32=0, 100, 100-(K32/J32)*100) -> 100 | M32: 1 | N32: 2.6
A33: 2 | B33: 46133 | C33: Steven | D33: 6 | E33: 248A1 | F33: A | G33: DT | H33: NA | I33: 7 | J33: 4 | K33: 0 | L33: =IF(K33=0, 100, 100-(K33/J33)*100) -> 100 | M33: 2 | N33: 1.4
A34: 2 | B34: 46133 | C34: Steven | D34: 6 | E34: 248A2 | F34: A | G34: DT | H34: NA | I34: 10 | J34: 4 | K34: 0 | L34: =IF(K34=0, 100, 100-(K34/J34)*100) -> 100 | M34: 2 | N34: 1.7
A35: 2 | B35: 46133 | C35: Steven | D35: 6 | E35: 250A1 | F35: A | G35: DT | H35: NA | I35: 14 | J35: 5 | K35: 0 | L35: =IF(K35=0, 100, 100-(K35/J35)*100) -> 100 | M35: 1 | N35: 1.7
A36: 2 | B36: 46133 | C36: Steven | D36: 6 | E36: 252A1 | F36: A | G36: AC | H36: NA | I36: 17 | J36: 3 | K36: 0 | L36: =IF(K36=0, 100, 100-(K36/J36)*100) -> 100 | M36: 2 | N36: 1.1
A37: 2 | B37: 46133 | C37: Steven | D37: 6 | E37: 252A2 | F37: A | G37: AC | H37: NA | I37: 13 | J37: 7 | K37: 0 | L37: =IF(K37=0, 100, 100-(K37/J37)*100) -> 100 | M37: 2 | N37: 2.4
A38: 2 | B38: 46133 | C38: Steven | D38: 6 | E38: 253A1 | F38: A | G38: AC | H38: NA | I38: 13 | J38: 7 | K38: 0 | L38: =IF(K38=0, 100, 100-(K38/J38)*100) -> 100 | M38: 2 | N38: 1.7
A39: 2 | B39: 46133 | C39: Steven | D39: 6 | E39: 253A2 | F39: A | G39: AC | H39: NA | I39: 14 | J39: 6 | K39: 0 | L39: =IF(K39=0, 100, 100-(K39/J39)*100) -> 100 | M39: 2 | N39: 1.3

Sheet Input2
A1: Page Number | B1: Date Collected | C1: Recorder | D1: Block | E1: Tag # | F1: Oak Type | G1: Treatment | H1: OA Microclimate | I1: Seedling Height | J1: # of Leaves | K1: # of dead leaves | L1: % Leaf Greeness | M1: # that germinated | N1: RCD | O1: Notes
A2: Page # | B2: MM/DD/YYYY | C2: Name | D2: # | E2: # | F2: NR, S, or A | G2: AC, OA, NP, DT, or DL | H2: TH, TI, CN | I2: (cm) | J2: # | K2: # | L2: % | M2: # | N2: (mm) | O2: as written on data sheet
A3: 1 | B3: 46133 | C3: JA/SM | D3: 7 | E3: 242A1 | F3: A | G3: AC | H3: NA | I3: 15 | J3: 4 | K3: 0 | L3: =IF(K3=0, 100, 100-(K3/J3)*100) -> 100 | M3: 3 | N3: 2.5
A4: 1 | B4: 46133 | C4: JA/SM | D4: 7 | E4: 242A2 | F4: A | G4: AC | H4: NA | I4: 20 | J4: 4 | K4: 0 | L4: =IF(K4=0, 100, 100-(K4/J4)*100) -> 100 | M4: 3 | N4: 2.9
A5: 1 | B5: 46133 | C5: JA/SM | D5: 7 | E5: 242A3 | F5: A | G5: AC | H5: NA | I5: 13 | J5: 5 | K5: 0 | L5: =IF(K5=0, 100, 100-(K5/J5)*100) -> 100 | M5: 3 | N5: 1.9
A6: 1 | B6: 46133 | C6: JA/SM | D6: 7 | E6: 222 | F6: NR | G6: AC | H6: NA | I6: 20 | J6: 3 | K6: 0 | L6: =IF(K6=0, 100, 100-(K6/J6)*100) -> 100 | M6: NA | N6: 3
A7: 1 | B7: 46133 | C7: JA/SM | D7: 7 | E7: 224 | F7: NR | G7: DL | H7: NA | I7: 21 | J7: 9 | K7: 0 | L7: =IF(K7=0, 100, 100-(K7/J7)*100) -> 100 | M7: NA | N7: 2.9
A8: 1 | B8: 46133 | C8: JA/SM | D8: 7 | E8: 244 | F8: A | G8: AC | H8: NA | I8: NA | J8: NA | K8: NA | L8: =IF(K8=0, 100, 100-(K8/J8)*100) -> #VALUE! | M8: 0 | N8: NA
A9: 1 | B9: 46133 | C9: JA/SM | D9: 7 | E9: 243A1 | F9: A | G9: AC | H9: NA | I9: 18 | J9: 2 | K9: 0 | L9: =IF(K9=0, 100, 100-(K9/J9)*100) -> 100 | M9: 2 | N9: 2.8
A10: 1 | B10: 46133 | C10: JA/SM | D10: 7 | E10: 243A2 | F10: A | G10: AC | H10: NA | I10: 12 | J10: 4 | K10: 0 | L10: =IF(K10=0, 100, 100-(K10/J10)*100) -> 100 | M10: 2 | N10: 1.5
A11: 1 | B11: 46133 | C11: JA/SM | D11: 7 | E11: 159A1 | F11: A | G11: AC | H11: NA | I11: 23 | J11: 14 | K11: 0 | L11: =IF(K11=0, 100, 100-(K11/J11)*100) -> 100 | M11: 3 | N11: 1.9
A12: 1 | B12: 46133 | C12: JA/SM | D12: 7 | E12: 159A3 | F12: A | G12: AC | H12: NA | I12: 13 | J12: 6 | K12: 0 | L12: =IF(K12=0, 100, 100-(K12/J12)*100) -> 100 | M12: 3 | N12: 1.4
A13: 1 | B13: 46133 | C13: JA/SM | D13: 7 | E13: 159A2 | F13: A | G13: AC | H13: NA | I13: 15 | J13: 9 | K13: 0 | L13: =IF(K13=0, 100, 100-(K13/J13)*100) -> 100 | M13: 3 | N13: 1
A14: 1 | B14: 46133 | C14: JA/SM | D14: 7 | E14: 204 | F14: NR | G14: AC | H14: NA | I14: 60 | J14: 90 | K14: 5 | L14: =IF(K14=0, 100, 100-(K14/J14)*100) -> 94.444444 | M14: NA | N14: 9
A15: 1 | B15: 46133 | C15: JA/SM | D15: 7 | E15: 219 | F15: NR | G15: DT | H15: NA | I15: 10 | J15: 12 | K15: 0 | L15: =IF(K15=0, 100, 100-(K15/J15)*100) -> 100 | M15: NA | N15: 2.7
A16: 1 | B16: 46133 | C16: JA/SM | D16: 7 | E16: 218 | F16: NR | G16: DT | H16: NA | I16: 19 | J16: 15 | K16: 0 | L16: =IF(K16=0, 100, 100-(K16/J16)*100) -> 100 | M16: NA | N16: 4.1
A17: 1 | B17: 46133 | C17: JA/SM | D17: 7 | E17: 240 | F17: A | G17: DT | H17: NA | I17: NA | J17: NA | K17: NA | L17: =IF(K17=0, 100, 100-(K17/J17)*100) -> #VALUE! | M17: NA | N17: NA
A18: 1 | B18: 46133 | C18: JA/SM | D18: 7 | E18: 239A1 | F18: A | G18: DT | H18: NA | I18: 21 | J18: 5 | K18: 0 | L18: =IF(K18=0, 100, 100-(K18/J18)*100) -> 100 | M18: 1 | N18: 2.1
A19: 1 | B19: 46133 | C19: JA/SM | D19: 7 | E19: 237 | F19: A | G19: OA | H19: CN | I19: NA | J19: NA | K19: NA | L19: =IF(K19=0, 100, 100-(K19/J19)*100) -> #VALUE! | M19: NA | N19: NA
A20: 1 | B20: 46133 | C20: JA/SM | D20: 7 | E20: 236 | F20: A | G20: OA | H20: TH | I20: NA | J20: NA | K20: NA | L20: =IF(K20=0, 100, 100-(K20/J20)*100) -> #VALUE! | M20: NA | N20: NA
A21: 1 | B21: 46133 | C21: JA/SM | D21: 7 | E21: 238 | F21: A | G21: OA | H21: TI | I21: 8 | J21: 8 | K21: 0 | L21: =IF(K21=0, 100, 100-(K21/J21)*100) -> 100 | M21: 1 | N21: 2
A22: 2 | B22: 46133 | C22: Steven | D22: 7 | E22: 152 | F22: A | G22: OA | H22: NA | I22: 14 | J22: 14 | K22: 0 | L22: =IF(K22=0, 100, 100-(K22/J22)*100) -> 100 | M22: 1 | N22: 0.8
A23: 2 | B23: 46133 | C23: Steven | D23: 6 | E23: 251 | F23: A | G23: AC | H23: NA | I23: 11 | J23: 4 | K23: 0 | L23: =IF(K23=0, 100, 100-(K23/J23)*100) -> 100 | M23: 1 | N23: 1.2
A24: 2 | B24: 46133 | C24: Steven | D24: 6 | E24: 253A1 | F24: A | G24: AC | H24: NA | I24: 13 | J24: 7 | K24: 0 | L24: =IF(K24=0, 100, 100-(K24/J24)*100) -> 100 | M24: 2 | N24: 1.7
A25: 2 | B25: 46133 | C25: Steven | D25: 6 | E25: 253A2 | F25: A | G25: AC | H25: NA | I25: 14 | J25: 6 | K25: 0 | L25: =IF(K25=0, 100, 100-(K25/J25)*100) -> 100 | M25: 2 | N25: 1.3
A26: 2 | B26: 46133 | C26: Steven | D26: 6 | E26: 252A1 | F26: A | G26: AC | H26: NA | I26: 17 | J26: 3 | K26: 0 | L26: =IF(K26=0, 100, 100-(K26/J26)*100) -> 100 | M26: 2 | N26: 1.1
A27: 2 | B27: 46133 | C27: Steven | D27: 6 | E27: 252A2 | F27: A | G27: AC | H27: NA | I27: 13 | J27: 7 | K27: 0 | L27: =IF(K27=0, 100, 100-(K27/J27)*100) -> 100 | M27: 2 | N27: 2.4
A28: 2 | B28: 46133 | C28: Steven | D28: 6 | E28: 247A1 | F28: A | G28: OA | H28: CN | I28: 13 | J28: 5 | K28: 0 | L28: =IF(K28=0, 100, 100-(K28/J28)*100) -> 100 | M28: 1 | N28: 2.6
A29: 2 | B29: 46133 | C29: Steven | D29: 6 | E29: 246 | F29: A | G29: OA | H29: TH | I29: NA | J29: NA | K29: NA | L29: =IF(K29=0, 100, 100-(K29/J29)*100) -> #VALUE! | M29: 0 | N29: NA
A30: 2 | B30: 46133 | C30: Steven | D30: 6 | E30: 245 | F30: A | G30: OA | H30: TI | I30: NA | J30: NA | K30: NA | L30: =IF(K30=0, 100, 100-(K30/J30)*100) -> #VALUE! | M30: 0 | N30: NA
A31: 2 | B31: 46133 | C31: Steven | D31: 6 | E31: 129A1 | F31: A | G31: OA | H31: NA | I31: NA | J31: NA | K31: NA | L31: =IF(K31=0, 100, 100-(K31/J31)*100) -> #VALUE! | M31: NA | N31: NA
A32: 2 | B32: 46133 | C32: Steven | D32: 6 | E32: 129A2 | F32: A | G32: OA | H32: NA | I32: 18 | J32: 25 | K32: 8 | L32: =IF(K32=0, 100, 100-(K32/J32)*100) -> 68 | M32: 2 | N32: 2.3
A33: 2 | B33: 46133 | C33: Steven | D33: 6 | E33: 127A1 | F33: A | G33: OA | H33: NA | I33: 36 | J33: 50 | K33: 0 | L33: =IF(K33=0, 100, 100-(K33/J33)*100) -> 100 | M33: 2 | N33: 7.9
A34: 2 | B34: 46133 | C34: Steven | D34: 6 | E34: 127A2 | F34: A | G34: OA | H34: NA | I34: 43 | J34: 90 | K34: 1 | L34: =IF(K34=0, 100, 100-(K34/J34)*100) -> 98.888889 | M34: 2 | N34: 6.6
A35: 2 | B35: 46133 | C35: Steven | D35: 6 | E35: 250A1 | F35: A | G35: DT | H35: NA | I35: 14 | J35: 5 | K35: 0 | L35: =IF(K35=0, 100, 100-(K35/J35)*100) -> 100 | M35: 1 | N35: 1.7
A36: 2 | B36: 46133 | C36: Steven | D36: 6 | E36: 248A1 | F36: A | G36: DT | H36: NA | I36: 7 | J36: 4 | K36: 0 | L36: =IF(K36=0, 100, 100-(K36/J36)*100) -> 100 | M36: 2 | N36: 1.4
A37: 2 | B37: 46133 | C37: Steven | D37: 6 | E37: 248A2 | F37: A | G37: DT | H37: NA | I37: 10 | J37: 4 | K37: 0 | L37: =IF(K37=0, 100, 100-(K37/J37)*100) -> 100 | M37: 2 | N37: 1.7
A38: 2 | B38: 46133 | C38: Steven | D38: 6 | E38: 225 | F38: NR | G38: DT | H38: NA | I38: 30 | J38: 30 | K38: 0 | L38: =IF(K38=0, 100, 100-(K38/J38)*100) -> 100 | M38: NA | N38: 7.4
A39: 2 | B39: 46133 | C39: Steven | D39: 6 | E39: 249 | F39: A | G39: DT | H39: NA | I39: NA | J39: NA | K39: NA | L39: =IF(K39=0, 100, 100-(K39/J39)*100) -> #VALUE! | M39: 0 | N39: NA
L40: =IF(K40=0, 100, 100-(K40/J40)*100) -> 100
...

Sheet Validation (Do not Edit)
A1: =IF(Input1!A1=Input2!A1, Input1!A1, "ERROR") -> Page Number | B1: =IF(Input1!B1=Input2!B1, Input1!B1, "ERROR") -> Date Collected | C1: =IF(Input1!C1=Input2!C1, Input1!C1, "ERROR") -> Recorder | D1: =IF(Input1!D1=Input2!D1, Input1!D1, "ERROR") -> Block | E1: =IF(Input1!E1=Input2!E1, Input1!E1, "ERROR") -> Tag # | F1: =IF(Input1!F1=Input2!F1, Input1!F1, "ERROR") -> Oak Type | G1: =IF(Input1!G1=Input2!G1, Input1!G1, "ERROR") -> Treatment | H1: =IF(Input1!H1=Input2!H1, Input1!H1, "ERROR") -> OA Microclimate | ... O1: =IF(Input1!O1=Input2!O1, Input1!O1, "ERROR") -> Notes
A2: =IF(Input1!A2=Input2!A2, Input1!A2, "ERROR") -> ERROR | B2: =IF(Input1!B2=Input2!B2, Input1!B2, "ERROR") -> ERROR | C2: =IF(Input1!C2=Input2!C2, Input1!C2, "ERROR") -> ERROR | D2: =IF(Input1!D2=Input2!D2, Input1!D2, "ERROR") -> ERROR | E2: =IF(Input1!E2=Input2!E2, Input1!E2, "ERROR") -> ERROR | F2: =IF(Input1!F2=Input2!F2, Input1!F2, "ERROR") -> ERROR | G2: =IF(Input1!G2=Input2!G2, Input1!G2, "ERROR") -> ERROR | H2: =IF(Input1!H2=Input2!H2, Input1!H2, "ERROR") -> ERROR | ... O2: =IF(Input1!O2=Input2!O2, Input1!O2, "ERROR") -> ERROR
A3: =IF(Input1!A3=Input2!A3, Input1!A3, "ERROR") -> 1 | B3: =IF(Input1!B3=Input2!B3, Input1!B3, "ERROR") -> 46133 | C3: =IF(Input1!C3=Input2!C3, Input1!C3, "ERROR") -> JA/SM | D3: =IF(Input1!D3=Input2!D3, Input1!D3, "ERROR") -> 7 | E3: =IF(Input1!E3=Input2!E3, Input1!E3, "ERROR") -> ERROR | F3: =IF(Input1!F3=Input2!F3, Input1!F3, "ERROR") -> ERROR | G3: =IF(Input1!G3=Input2!G3, Input1!G3, "ERROR") -> AC | H3: =IF(Input1!H3=Input2!H3, Input1!H3, "ERROR") -> NA | ... O3: =IF(Input1!O3=Input2!O3, Input1!O3, "ERROR") -> 0
A4: =IF(Input1!A4=Input2!A4, Input1!A4, "ERROR") -> 1 | B4: =IF(Input1!B4=Input2!B4, Input1!B4, "ERROR") -> 46133 | C4: =IF(Input1!C4=Input2!C4, Input1!C4, "ERROR") -> JA/SM | D4: =IF(Input1!D4=Input2!D4, Input1!D4, "ERROR") -> 7 | E4: =IF(Input1!E4=Input2!E4, Input1!E4, "ERROR") -> ERROR | F4: =IF(Input1!F4=Input2!F4, Input1!F4, "ERROR") -> ERROR | G4: =IF(Input1!G4=Input2!G4, Input1!G4, "ERROR") -> ERROR | H4: =IF(Input1!H4=Input2!H4, Input1!H4, "ERROR") -> NA | ... O4: =IF(Input1!O4=Input2!O4, Input1!O4, "ERROR") -> ERROR
A5: =IF(Input1!A5=Input2!A5, Input1!A5, "ERROR") -> 1 | B5: =IF(Input1!B5=Input2!B5, Input1!B5, "ERROR") -> 46133 | C5: =IF(Input1!C5=Input2!C5, Input1!C5, "ERROR") -> JA/SM | D5: =IF(Input1!D5=Input2!D5, Input1!D5, "ERROR") -> 7 | E5: =IF(Input1!E5=Input2!E5, Input1!E5, "ERROR") -> ERROR | F5: =IF(Input1!F5=Input2!F5, Input1!F5, "ERROR") -> ERROR | G5: =IF(Input1!G5=Input2!G5, Input1!G5, "ERROR") -> ERROR | H5: =IF(Input1!H5=Input2!H5, Input1!H5, "ERROR") -> NA | ... O5: =IF(Input1!O5=Input2!O5, Input1!O5, "ERROR") -> 0
A6: =IF(Input1!A6=Input2!A6, Input1!A6, "ERROR") -> 1 | B6: =IF(Input1!B6=Input2!B6, Input1!B6, "ERROR") -> 46133 | C6: =IF(Input1!C6=Input2!C6, Input1!C6, "ERROR") -> JA/SM | D6: =IF(Input1!D6=Input2!D6, Input1!D6, "ERROR") -> 7 | E6: =IF(Input1!E6=Input2!E6, Input1!E6, "ERROR") -> 222 | F6: =IF(Input1!F6=Input2!F6, Input1!F6, "ERROR") -> NR | G6: =IF(Input1!G6=Input2!G6, Input1!G6, "ERROR") -> AC | H6: =IF(Input1!H6=Input2!H6, Input1!H6, "ERROR") -> NA | ... O6: =IF(Input1!O6=Input2!O6, Input1!O6, "ERROR") -> 0
A7: =IF(Input1!A7=Input2!A7, Input1!A7, "ERROR") -> 1 | B7: =IF(Input1!B7=Input2!B7, Input1!B7, "ERROR") -> 46133 | C7: =IF(Input1!C7=Input2!C7, Input1!C7, "ERROR") -> JA/SM | D7: =IF(Input1!D7=Input2!D7, Input1!D7, "ERROR") -> 7 | E7: =IF(Input1!E7=Input2!E7, Input1!E7, "ERROR") -> 224 | F7: =IF(Input1!F7=Input2!F7, Input1!F7, "ERROR") -> NR | G7: =IF(Input1!G7=Input2!G7, Input1!G7, "ERROR") -> DL | H7: =IF(Input1!H7=Input2!H7, Input1!H7, "ERROR") -> NA | ... O7: =IF(Input1!O7=Input2!O7, Input1!O7, "ERROR") -> 0
A8: =IF(Input1!A8=Input2!A8, Input1!A8, "ERROR") -> ERROR | B8: =IF(Input1!B8=Input2!B8, Input1!B8, "ERROR") -> 46133 | C8: =IF(Input1!C8=Input2!C8, Input1!C8, "ERROR") -> ERROR | D8: =IF(Input1!D8=Input2!D8, Input1!D8, "ERROR") -> ERROR | E8: =IF(Input1!E8=Input2!E8, Input1!E8, "ERROR") -> ERROR | F8: =IF(Input1!F8=Input2!F8, Input1!F8, "ERROR") -> ERROR | G8: =IF(Input1!G8=Input2!G8, Input1!G8, "ERROR") -> ERROR | H8: =IF(Input1!H8=Input2!H8, Input1!H8, "ERROR") -> NA | ... O8: =IF(Input1!O8=Input2!O8, Input1!O8, "ERROR") -> 0
A9: =IF(Input1!A9=Input2!A9, Input1!A9, "ERROR") -> 1 | B9: =IF(Input1!B9=Input2!B9, Input1!B9, "ERROR") -> 46133 | C9: =IF(Input1!C9=Input2!C9, Input1!C9, "ERROR") -> JA/SM | D9: =IF(Input1!D9=Input2!D9, Input1!D9, "ERROR") -> 7 | E9: =IF(Input1!E9=Input2!E9, Input1!E9, "ERROR") -> ERROR | F9: =IF(Input1!F9=Input2!F9, Input1!F9, "ERROR") -> A | G9: =IF(Input1!G9=Input2!G9, Input1!G9, "ERROR") -> ERROR | H9: =IF(Input1!H9=Input2!H9, Input1!H9, "ERROR") -> ERROR | ... O9: =IF(Input1!O9=Input2!O9, Input1!O9, "ERROR") -> 0
A10: =IF(Input1!A10=Input2!A10, Input1!A10, "ERROR") -> 1 | B10: =IF(Input1!B10=Input2!B10, Input1!B10, "ERROR") -> 46133 | C10: =IF(Input1!C10=Input2!C10, Input1!C10, "ERROR") -> JA/SM | D10: =IF(Input1!D10=Input2!D10, Input1!D10, "ERROR") -> 7 | E10: =IF(Input1!E10=Input2!E10, Input1!E10, "ERROR") -> ERROR | F10: =IF(Input1!F10=Input2!F10, Input1!F10, "ERROR") -> A | G10: =IF(Input1!G10=Input2!G10, Input1!G10, "ERROR") -> ERROR | H10: =IF(Input1!H10=Input2!H10, Input1!H10, "ERROR") -> ERROR | ... O10: =IF(Input1!O10=Input2!O10, Input1!O10, "ERROR") -> 0
A11: =IF(Input1!A11=Input2!A11, Input1!A11, "ERROR") -> 1 | B11: =IF(Input1!B11=Input2!B11, Input1!B11, "ERROR") -> 46133 | C11: =IF(Input1!C11=Input2!C11, Input1!C11, "ERROR") -> JA/SM | D11: =IF(Input1!D11=Input2!D11, Input1!D11, "ERROR") -> 7 | E11: =IF(Input1!E11=Input2!E11, Input1!E11, "ERROR") -> ERROR | F11: =IF(Input1!F11=Input2!F11, Input1!F11, "ERROR") -> A | G11: =IF(Input1!G11=Input2!G11, Input1!G11, "ERROR") -> ERROR | H11: =IF(Input1!H11=Input2!H11, Input1!H11, "ERROR") -> ERROR | ... O11: =IF(Input1!O11=Input2!O11, Input1!O11, "ERROR") -> 0
A12: =IF(Input1!A12=Input2!A12, Input1!A12, "ERROR") -> 1 | B12: =IF(Input1!B12=Input2!B12, Input1!B12, "ERROR") -> 46133 | C12: =IF(Input1!C12=Input2!C12, Input1!C12, "ERROR") -> JA/SM | D12: =IF(Input1!D12=Input2!D12, Input1!D12, "ERROR") -> 7 | E12: =IF(Input1!E12=Input2!E12, Input1!E12, "ERROR") -> ERROR | F12: =IF(Input1!F12=Input2!F12, Input1!F12, "ERROR") -> A | G12: =IF(Input1!G12=Input2!G12, Input1!G12, "ERROR") -> ERROR | H12: =IF(Input1!H12=Input2!H12, Input1!H12, "ERROR") -> NA | ... O12: =IF(Input1!O12=Input2!O12, Input1!O12, "ERROR") -> 0
... A186: =IF(Input1!A186=Input2!A186, Input1!A186, "ERROR") -> 0 | B186: =IF(Input1!B186=Input2!B186, Input1!B186, "ERROR") -> 0 | C186: =IF(Input1!C186=Input2!C186, Input1!C186, "ERROR") -> 0 | D186: =IF(Input1!D186=Input2!D186, Input1!D186, "ERROR") -> 0 | E186: =IF(Input1!E186=Input2!E186, Input1!E186, "ERROR") -> 0 | F186: =IF(Input1!F186=Input2!F186, Input1!F186, "ERROR") -> 0 | G186: =IF(Input1!G186=Input2!G186, Input1!G186, "ERROR") -> 0 | H186: =IF(Input1!H186=Input2!H186, Input1!H186, "ERROR") -> 0 | ... O186: =IF(Input1!O186=Input2!O186, Input1!O186, "ERROR") -> 0
